Workbook

Sheet Cover
B2: [DEAL] — Structured Finance / Securitization Model
B4: Asset class: | C4: RMBS / ABS / CLO
B5: Closing date: | C5: [date]
B6: Last refreshed: | C6: [date]
B7: Refresh cadence: | C7: Weekly (monthly at distribution date)

Sheet Collateral Pool
B2: Collateral Pool Summary
B5: Aggregate pool balance ($) | C5: 0
B6: Weighted avg coupon (WAC, %) | C6: 0.06
B7: Weighted avg maturity (WAM, months) | C7: 360
B8: Conditional prepayment rate assumption (CPR, %) | C8: 0.08
B9: Conditional default rate assumption (CDR, annual %) | C9: 0.03
B10: Recovery rate on defaults (%) | C10: 0.5
B11: Recovery lag (months from default to cash) | C11: 3
B13: Single Monthly Mortality (SMM) from CPR | C13: =1-(1-C8)^(1/12) -> 0.0069243826 | D13: SMM = 1-(1-CPR)^(1/12) — standard CPR-to-SMM conversion
B14: Monthly Default Rate (MDR) from CDR | C14: =1-(1-C9)^(1/12) -> 0.0025350486 | D14: MDR = 1-(1-CDR)^(1/12) — same conditional-rate-to-monthly conversion as SMM, applied to defaults instead of prepayments
B15: Scheduled monthly P&I payment (level-pay amortization) | C15: =IFERROR(C5*(C6/12)/(1-(1+C6/12)^(-C7)),"-") -> 0 | D15: Standard mortgage-style level payment: Balance x (WAC/12) / (1-(1+WAC/12)^-WAM). Constant $ payment; the interest/principal split shifts over time as the balance amortizes.

Sheet Waterfall
B2: Tranche Structure & Credit Enhancement
B4: Tranche | C4: Face ($) | D4: % of pool | E4: Coupon | F4: Credit enhancement % | G4: Notes
B5: Class A (senior) | C5: 0 | D5: =IFERROR(C5/$C$10,"-") -> - | E5: 0 | F5: =IFERROR(SUM(C6:C9)/$C$10,"-") -> -
B6: Class B (mezz) | C6: 0 | D6: =IFERROR(C6/$C$10,"-") -> - | E6: 0 | F6: =IFERROR(SUM(C7:C9)/$C$10,"-") -> -
B7: Class C (mezz) | C7: 0 | D7: =IFERROR(C7/$C$10,"-") -> - | E7: 0 | F7: =IFERROR(SUM(C8:C9)/$C$10,"-") -> -
B8: Class D (subordinate) | C8: 0 | D8: =IFERROR(C8/$C$10,"-") -> - | E8: 0 | F8: =IFERROR(SUM(C9:C9)/$C$10,"-") -> -
B9: Equity / residual | C9: 0 | D9: =IFERROR(C9/$C$10,"-") -> - | E9: 0 | F9: =IFERROR(SUM(C10:C9)/$C$10,"-") -> -
B10: Total | C10: =SUM(C5:C9) -> 0
B12: CE% for a tranche = subordinate tranche cushion that absorbs losses before it does

Sheet Tranche Cash Flow Waterfall
B2: 12-Month Tranche Cash Flow Waterfall
B4: Pool Cash Flow | C4: M1 | D4: M2 | E4: M3 | F4: M4 | G4: M5 | H4: M6 | I4: M7 | J4: M8 | K4: M9 | L4: M10 | M4: M11 | N4: M12
B5: Beginning balance | C5: ='Collateral Pool'!$C$5 -> 0 | D5: =C12 -> 0 | E5: =D12 -> 0 | F5: =E12 -> 0 | G5: =F12 -> 0 | H5: =G12 -> 0 | I5: =H12 -> 0 | J5: =I12 -> 0 | K5: =J12 -> 0 | ... N5: =M12 -> 0
B6: Scheduled interest (WAC/12 x beg.) | C6: =C5*'Collateral Pool'!$C$6/12 -> 0 | D6: =D5*'Collateral Pool'!$C$6/12 -> 0 | E6: =E5*'Collateral Pool'!$C$6/12 -> 0 | F6: =F5*'Collateral Pool'!$C$6/12 -> 0 | G6: =G5*'Collateral Pool'!$C$6/12 -> 0 | H6: =H5*'Collateral Pool'!$C$6/12 -> 0 | I6: =I5*'Collateral Pool'!$C$6/12 -> 0 | J6: =J5*'Collateral Pool'!$C$6/12 -> 0 | ... N6: =N5*'Collateral Pool'!$C$6/12 -> 0
B7: Scheduled principal (level-pay P&I - interest) | C7: =MAX(0,'Collateral Pool'!$C$15-C6) -> 0 | D7: =MAX(0,'Collateral Pool'!$C$15-D6) -> 0 | E7: =MAX(0,'Collateral Pool'!$C$15-E6) -> 0 | F7: =MAX(0,'Collateral Pool'!$C$15-F6) -> 0 | G7: =MAX(0,'Collateral Pool'!$C$15-G6) -> 0 | H7: =MAX(0,'Collateral Pool'!$C$15-H6) -> 0 | I7: =MAX(0,'Collateral Pool'!$C$15-I6) -> 0 | J7: =MAX(0,'Collateral Pool'!$C$15-J6) -> 0 | ... N7: =MAX(0,'Collateral Pool'!$C$15-N6) -> 0
B8: Defaults (MDR x beg.) | C8: =C5*'Collateral Pool'!$C$14 -> 0 | D8: =D5*'Collateral Pool'!$C$14 -> 0 | E8: =E5*'Collateral Pool'!$C$14 -> 0 | F8: =F5*'Collateral Pool'!$C$14 -> 0 | G8: =G5*'Collateral Pool'!$C$14 -> 0 | H8: =H5*'Collateral Pool'!$C$14 -> 0 | I8: =I5*'Collateral Pool'!$C$14 -> 0 | J8: =J5*'Collateral Pool'!$C$14 -> 0 | ... N8: =N5*'Collateral Pool'!$C$14 -> 0
B9: Prepayments (SMM x remaining) | C9: =MAX(0,C5-C7-C8)*'Collateral Pool'!$C$13 -> 0 | D9: =MAX(0,D5-D7-D8)*'Collateral Pool'!$C$13 -> 0 | E9: =MAX(0,E5-E7-E8)*'Collateral Pool'!$C$13 -> 0 | F9: =MAX(0,F5-F7-F8)*'Collateral Pool'!$C$13 -> 0 | G9: =MAX(0,G5-G7-G8)*'Collateral Pool'!$C$13 -> 0 | H9: =MAX(0,H5-H7-H8)*'Collateral Pool'!$C$13 -> 0 | I9: =MAX(0,I5-I7-I8)*'Collateral Pool'!$C$13 -> 0 | J9: =MAX(0,J5-J7-J8)*'Collateral Pool'!$C$13 -> 0 | ... N9: =MAX(0,N5-N7-N8)*'Collateral Pool'!$C$13 -> 0
B10: Recovery proceeds (lagged, net of severity) | C10: 0 | D10: 0 | E10: 0 | F10: =C8*'Collateral Pool'!$C$10 -> 0 | G10: =D8*'Collateral Pool'!$C$10 -> 0 | H10: =E8*'Collateral Pool'!$C$10 -> 0 | I10: =F8*'Collateral Pool'!$C$10 -> 0 | J10: =G8*'Collateral Pool'!$C$10 -> 0 | K10: =H8*'Collateral Pool'!$C$10 -> 0 | L10: =I8*'Collateral Pool'!$C$10 -> 0 | M10: =J8*'Collateral Pool'!$C$10 -> 0 | N10: =K8*'Collateral Pool'!$C$10 -> 0
B11: Realized loss (defaults x (1 - recovery rate)) | C11: =C8*(1-'Collateral Pool'!$C$10) -> 0 | D11: =D8*(1-'Collateral Pool'!$C$10) -> 0 | E11: =E8*(1-'Collateral Pool'!$C$10) -> 0 | F11: =F8*(1-'Collateral Pool'!$C$10) -> 0 | G11: =G8*(1-'Collateral Pool'!$C$10) -> 0 | H11: =H8*(1-'Collateral Pool'!$C$10) -> 0 | I11: =I8*(1-'Collateral Pool'!$C$10) -> 0 | J11: =J8*(1-'Collateral Pool'!$C$10) -> 0 | ... N11: =N8*(1-'Collateral Pool'!$C$10) -> 0
B12: Ending balance | C12: =C5-C7-C8-C9 -> 0 | D12: =D5-D7-D8-D9 -> 0 | E12: =E5-E7-E8-E9 -> 0 | F12: =F5-F7-F8-F9 -> 0 | G12: =G5-G7-G8-G9 -> 0 | H12: =H5-H7-H8-H9 -> 0 | I12: =I5-I7-I8-I9 -> 0 | J12: =J5-J7-J8-J9 -> 0 | ... N12: =N5-N7-N8-N9 -> 0
B14: Principal available for tranches | C14: =C7+C9+C10 -> 0 | D14: =D7+D9+D10 -> 0 | E14: =E7+E9+E10 -> 0 | F14: =F7+F9+F10 -> 0 | G14: =G7+G9+G10 -> 0 | H14: =H7+H9+H10 -> 0 | I14: =I7+I9+I10 -> 0 | J14: =J7+J9+J10 -> 0 | ... N14: =N7+N9+N10 -> 0
B15: Loss to allocate to tranches | C15: =C11 -> 0 | D15: =D11 -> 0 | E15: =E11 -> 0 | F15: =F11 -> 0 | G15: =G11 -> 0 | H15: =H11 -> 0 | I15: =I11 -> 0 | J15: =J11 -> 0 | ... N15: =N11 -> 0
B16: Recovery lag fixed at 3 months to match Collateral Pool's default assumption — if you change that input, update RECOVERY_LAG_MONTHS in the builder and regenerate, since the lag is baked into which column each recovery formula references, not read dynamically.
B19: Class A (senior)
B20: Beginning balance | C20: =Waterfall!C5 -> 0 | D20: =C23 -> 0 | E20: =D23 -> 0 | F20: =E23 -> 0 | G20: =F23 -> 0 | H20: =G23 -> 0 | I20: =H23 -> 0 | J20: =I23 -> 0 | K20: =J23 -> 0 | ... N20: =M23 -> 0
B21: Principal received | C21: =MAX(0,MIN(C14,C20)) -> 0 | D21: =MAX(0,MIN(D14,D20)) -> 0 | E21: =MAX(0,MIN(E14,E20)) -> 0 | F21: =MAX(0,MIN(F14,F20)) -> 0 | G21: =MAX(0,MIN(G14,G20)) -> 0 | H21: =MAX(0,MIN(H14,H20)) -> 0 | I21: =MAX(0,MIN(I14,I20)) -> 0 | J21: =MAX(0,MIN(J14,J20)) -> 0 | ... N21: =MAX(0,MIN(N14,N20)) -> 0
B22: Loss allocated | C22: =MAX(0,MIN(C15-C42-C37-C32-C27,(C20-C21))) -> 0 | D22: =MAX(0,MIN(D15-D42-D37-D32-D27,(D20-D21))) -> 0 | E22: =MAX(0,MIN(E15-E42-E37-E32-E27,(E20-E21))) -> 0 | F22: =MAX(0,MIN(F15-F42-F37-F32-F27,(F20-F21))) -> 0 | G22: =MAX(0,MIN(G15-G42-G37-G32-G27,(G20-G21))) -> 0 | H22: =MAX(0,MIN(H15-H42-H37-H32-H27,(H20-H21))) -> 0 | I22: =MAX(0,MIN(I15-I42-I37-I32-I27,(I20-I21))) -> 0 | J22: =MAX(0,MIN(J15-J42-J37-J32-J27,(J20-J21))) -> 0 | ... N22: =MAX(0,MIN(N15-N42-N37-N32-N27,(N20-N21))) -> 0
B23: Ending balance | C23: =C20-C21-C22 -> 0 | D23: =D20-D21-D22 -> 0 | E23: =E20-E21-E22 -> 0 | F23: =F20-F21-F22 -> 0 | G23: =G20-G21-G22 -> 0 | H23: =H20-H21-H22 -> 0 | I23: =I20-I21-I22 -> 0 | J23: =J20-J21-J22 -> 0 | ... N23: =N20-N21-N22 -> 0
B24: Class B (mezz)
B25: Beginning balance | C25: =Waterfall!C6 -> 0 | D25: =C28 -> 0 | E25: =D28 -> 0 | F25: =E28 -> 0 | G25: =F28 -> 0 | H25: =G28 -> 0 | I25: =H28 -> 0 | J25: =I28 -> 0 | K25: =J28 -> 0 | ... N25: =M28 -> 0
B26: Principal received | C26: =MAX(0,MIN(C14-C21,C25)) -> 0 | D26: =MAX(0,MIN(D14-D21,D25)) -> 0 | E26: =MAX(0,MIN(E14-E21,E25)) -> 0 | F26: =MAX(0,MIN(F14-F21,F25)) -> 0 | G26: =MAX(0,MIN(G14-G21,G25)) -> 0 | H26: =MAX(0,MIN(H14-H21,H25)) -> 0 | I26: =MAX(0,MIN(I14-I21,I25)) -> 0 | J26: =MAX(0,MIN(J14-J21,J25)) -> 0 | ... N26: =MAX(0,MIN(N14-N21,N25)) -> 0
B27: Loss allocated | C27: =MAX(0,MIN(C15-C42-C37-C32,(C25-C26))) -> 0 | D27: =MAX(0,MIN(D15-D42-D37-D32,(D25-D26))) -> 0 | E27: =MAX(0,MIN(E15-E42-E37-E32,(E25-E26))) -> 0 | F27: =MAX(0,MIN(F15-F42-F37-F32,(F25-F26))) -> 0 | G27: =MAX(0,MIN(G15-G42-G37-G32,(G25-G26))) -> 0 | H27: =MAX(0,MIN(H15-H42-H37-H32,(H25-H26))) -> 0 | I27: =MAX(0,MIN(I15-I42-I37-I32,(I25-I26))) -> 0 | J27: =MAX(0,MIN(J15-J42-J37-J32,(J25-J26))) -> 0 | ... N27: =MAX(0,MIN(N15-N42-N37-N32,(N25-N26))) -> 0
B28: Ending balance | C28: =C25-C26-C27 -> 0 | D28: =D25-D26-D27 -> 0 | E28: =E25-E26-E27 -> 0 | F28: =F25-F26-F27 -> 0 | G28: =G25-G26-G27 -> 0 | H28: =H25-H26-H27 -> 0 | I28: =I25-I26-I27 -> 0 | J28: =J25-J26-J27 -> 0 | ... N28: =N25-N26-N27 -> 0
B29: Class C (mezz)
B30: Beginning balance | C30: =Waterfall!C7 -> 0 | D30: =C33 -> 0 | E30: =D33 -> 0 | F30: =E33 -> 0 | G30: =F33 -> 0 | H30: =G33 -> 0 | I30: =H33 -> 0 | J30: =I33 -> 0 | K30: =J33 -> 0 | ... N30: =M33 -> 0
B31: Principal received | C31: =MAX(0,MIN(C14-C21-C26,C30)) -> 0 | D31: =MAX(0,MIN(D14-D21-D26,D30)) -> 0 | E31: =MAX(0,MIN(E14-E21-E26,E30)) -> 0 | F31: =MAX(0,MIN(F14-F21-F26,F30)) -> 0 | G31: =MAX(0,MIN(G14-G21-G26,G30)) -> 0 | H31: =MAX(0,MIN(H14-H21-H26,H30)) -> 0 | I31: =MAX(0,MIN(I14-I21-I26,I30)) -> 0 | J31: =MAX(0,MIN(J14-J21-J26,J30)) -> 0 | ... N31: =MAX(0,MIN(N14-N21-N26,N30)) -> 0
B32: Loss allocated | C32: =MAX(0,MIN(C15-C42-C37,(C30-C31))) -> 0 | D32: =MAX(0,MIN(D15-D42-D37,(D30-D31))) -> 0 | E32: =MAX(0,MIN(E15-E42-E37,(E30-E31))) -> 0 | F32: =MAX(0,MIN(F15-F42-F37,(F30-F31))) -> 0 | G32: =MAX(0,MIN(G15-G42-G37,(G30-G31))) -> 0 | H32: =MAX(0,MIN(H15-H42-H37,(H30-H31))) -> 0 | I32: =MAX(0,MIN(I15-I42-I37,(I30-I31))) -> 0 | J32: =MAX(0,MIN(J15-J42-J37,(J30-J31))) -> 0 | ... N32: =MAX(0,MIN(N15-N42-N37,(N30-N31))) -> 0
B33: Ending balance | C33: =C30-C31-C32 -> 0 | D33: =D30-D31-D32 -> 0 | E33: =E30-E31-E32 -> 0 | F33: =F30-F31-F32 -> 0 | G33: =G30-G31-G32 -> 0 | H33: =H30-H31-H32 -> 0 | I33: =I30-I31-I32 -> 0 | J33: =J30-J31-J32 -> 0 | ... N33: =N30-N31-N32 -> 0
B34: Class D (subordinate)
B35: Beginning balance | C35: =Waterfall!C8 -> 0 | D35: =C38 -> 0 | E35: =D38 -> 0 | F35: =E38 -> 0 | G35: =F38 -> 0 | H35: =G38 -> 0 | I35: =H38 -> 0 | J35: =I38 -> 0 | K35: =J38 -> 0 | ... N35: =M38 -> 0
B36: Principal received | C36: =MAX(0,MIN(C14-C21-C26-C31,C35)) -> 0 | D36: =MAX(0,MIN(D14-D21-D26-D31,D35)) -> 0 | E36: =MAX(0,MIN(E14-E21-E26-E31,E35)) -> 0 | F36: =MAX(0,MIN(F14-F21-F26-F31,F35)) -> 0 | G36: =MAX(0,MIN(G14-G21-G26-G31,G35)) -> 0 | H36: =MAX(0,MIN(H14-H21-H26-H31,H35)) -> 0 | I36: =MAX(0,MIN(I14-I21-I26-I31,I35)) -> 0 | J36: =MAX(0,MIN(J14-J21-J26-J31,J35)) -> 0 | ... N36: =MAX(0,MIN(N14-N21-N26-N31,N35)) -> 0
B37: Loss allocated | C37: =MAX(0,MIN(C15-C42,(C35-C36))) -> 0 | D37: =MAX(0,MIN(D15-D42,(D35-D36))) -> 0 | E37: =MAX(0,MIN(E15-E42,(E35-E36))) -> 0 | F37: =MAX(0,MIN(F15-F42,(F35-F36))) -> 0 | G37: =MAX(0,MIN(G15-G42,(G35-G36))) -> 0 | H37: =MAX(0,MIN(H15-H42,(H35-H36))) -> 0 | I37: =MAX(0,MIN(I15-I42,(I35-I36))) -> 0 | J37: =MAX(0,MIN(J15-J42,(J35-J36))) -> 0 | ... N37: =MAX(0,MIN(N15-N42,(N35-N36))) -> 0
B38: Ending balance | C38: =C35-C36-C37 -> 0 | D38: =D35-D36-D37 -> 0 | E38: =E35-E36-E37 -> 0 | F38: =F35-F36-F37 -> 0 | G38: =G35-G36-G37 -> 0 | H38: =H35-H36-H37 -> 0 | I38: =I35-I36-I37 -> 0 | J38: =J35-J36-J37 -> 0 | ... N38: =N35-N36-N37 -> 0
B39: Equity / residual
B40: Beginning balance | C40: =Waterfall!C9 -> 0 | D40: =C43 -> 0 | E40: =D43 -> 0 | F40: =E43 -> 0 | G40: =F43 -> 0 | H40: =G43 -> 0 | I40: =H43 -> 0 | J40: =I43 -> 0 | K40: =J43 -> 0 | ... N40: =M43 -> 0
B41: Principal received | C41: =MAX(0,MIN(C14-C21-C26-C31-C36,C40)) -> 0 | D41: =MAX(0,MIN(D14-D21-D26-D31-D36,D40)) -> 0 | E41: =MAX(0,MIN(E14-E21-E26-E31-E36,E40)) -> 0 | F41: =MAX(0,MIN(F14-F21-F26-F31-F36,F40)) -> 0 | G41: =MAX(0,MIN(G14-G21-G26-G31-G36,G40)) -> 0 | H41: =MAX(0,MIN(H14-H21-H26-H31-H36,H40)) -> 0 | I41: =MAX(0,MIN(I14-I21-I26-I31-I36,I40)) -> 0 | J41: =MAX(0,MIN(J14-J21-J26-J31-J36,J40)) -> 0 | ... N41: =MAX(0,MIN(N14-N21-N26-N31-N36,N40)) -> 0
B42: Loss allocated | C42: =MAX(0,MIN(C15,(C40-C41))) -> 0 | D42: =MAX(0,MIN(D15,(D40-D41))) -> 0 | E42: =MAX(0,MIN(E15,(E40-E41))) -> 0 | F42: =MAX(0,MIN(F15,(F40-F41))) -> 0 | G42: =MAX(0,MIN(G15,(G40-G41))) -> 0 | H42: =MAX(0,MIN(H15,(H40-H41))) -> 0 | I42: =MAX(0,MIN(I15,(I40-I41))) -> 0 | J42: =MAX(0,MIN(J15,(J40-J41))) -> 0 | ... N42: =MAX(0,MIN(N15,(N40-N41))) -> 0
B43: Ending balance | C43: =C40-C41-C42 -> 0 | D43: =D40-D41-D42 -> 0 | E43: =E40-E41-E42 -> 0 | F43: =F40-F41-F42 -> 0 | G43: =G40-G41-G42 -> 0 | H43: =H40-H41-H42 -> 0 | I43: =I40-I41-I42 -> 0 | J43: =J40-J41-J42 -> 0 | ... N43: =N40-N41-N42 -> 0
B45: Per-Tranche WAL (this 12-month window only)
B46: Class A (senior) | C46: =IFERROR(SUMPRODUCT(COLUMN(C21:N21)-COLUMN(C21)+1,C21:N21)/SUM(C21:N21)/12,"-") -> -
...

Sheet RefreshLog
B2: Refresh Log
B4: Date | C4: Trigger | D4: What changed | E4: Reviewer notes | F4: Next check
