Workbook

Sheet Cover
B2: [UNDERLYING] — Options Model
B4: Underlying: | C4: [fill in]
B5: Option type covered: | C5: Equity / index / FX / commodity options
B6: Last refreshed: | C6: [date]
B7: Next expiry to watch: | C7: [date]
B8: Refresh cadence: | C8: Weekly (daily near expiry)

Sheet BS Pricer
B2: Black-Scholes Pricer
B4: Inputs | E4: Intermediate
B5: Spot price (S) | C5: 100 | E5: d1 | F5: =(LN(C5/C6)+(C8-C9+0.5*C10^2)*C7)/(C10*SQRT(C7)) -> 0.15
B6: Strike price (K) | C6: 100 | E6: d2 | F6: =F5-C10*SQRT(C7) -> 0
B7: Time to expiry (yrs, T) | C7: 0.25 | E7: N(d1) | F7: =NORMSDIST(F5) -> 0.55961769
B8: Risk-free rate (r) | C8: 0.045 | E8: N(d2) | F8: =NORMSDIST(F6) -> 0.5
B9: Dividend yield (q) | C9: 0 | E9: N(-d1) | F9: =NORMSDIST(-F5) -> 0.44038231
B10: Implied volatility (sigma) | C10: 0.3 | E10: N(-d2) | F10: =NORMSDIST(-F6) -> 0.5
B12: Outputs
B13: Call price | C13: =C5*EXP(-C9*C7)*F7-C6*EXP(-C8*C7)*F8 -> 6.521117
B14: Put price | C14: =C6*EXP(-C8*C7)*F10-C5*EXP(-C9*C7)*F9 -> 5.4024215

Sheet Greeks
B2: Greeks (linked to BS Pricer inputs)
B4: Greek | C4: Call | D4: Put | E4: Interpretation
B5: Delta | C5: =EXP(-'BS Pricer'!$C$9*'BS Pricer'!$C$7)*'BS Pricer'!$F$7 -> 0.55961769 | D5: =-EXP(-'BS Pricer'!$C$9*'BS Pricer'!$C$7)*'BS Pricer'!$F$9 -> -0.44038231 | E5: Price sensitivity to $1 move in underlying
B6: Gamma | C6: =EXP(-'BS Pricer'!$C$9*'BS Pricer'!$C$7)*(EXP(-('BS Pricer'!$F$5)^2/2)/SQRT(2*PI()))/('BS Pricer'!$C$5*'BS Pricer'!$C$10*SQRT('BS Pricer'!$C$7)) -> 0.026897048 | D6: =EXP(-'BS Pricer'!$C$9*'BS Pricer'!$C$7)*(EXP(-('BS Pricer'!$F$5)^2/2)/SQRT(2*PI()))/('BS Pricer'!$C$5*'BS Pricer'!$C$10*SQRT('BS Pricer'!$C$7)) -> 0.026897048 | E6: Rate of change of delta
B7: Vega (per 1% vol) | C7: ='BS Pricer'!$C$5*EXP(-'BS Pricer'!$C$9*'BS Pricer'!$C$7)*(EXP(-('BS Pricer'!$F$5)^2/2)/SQRT(2*PI()))*SQRT('BS Pricer'!$C$7)/100 -> 0.20172786 | D7: ='BS Pricer'!$C$5*EXP(-'BS Pricer'!$C$9*'BS Pricer'!$C$7)*(EXP(-('BS Pricer'!$F$5)^2/2)/SQRT(2*PI()))*SQRT('BS Pricer'!$C$7)/100 -> 0.20172786 | E7: Sensitivity to 1pt vol change
B8: Theta (per day) | C8: =(-'BS Pricer'!$C$5*(EXP(-('BS Pricer'!$F$5)^2/2)/SQRT(2*PI()))*'BS Pricer'!$C$10*EXP(-'BS Pricer'!$C$9*'BS Pricer'!$C$7)/(2*SQRT('BS Pricer'!$C$7))-'BS Pricer'!$C$8*'BS Pricer'!$C$6*EXP(-'BS Pricer'!$C$8*'BS Pricer'!$C$7)*'BS Pricer'!$F$8+'BS Pricer'!$C$9*'BS Pricer'!$C$5*EXP(-'BS Pricer'!$C$9*'BS Pricer'!$C$7)*'BS Pricer'!$F$7)/365 -> -0.039256167 | D8: =(-'BS Pricer'!$C$5*(EXP(-('BS Pricer'!$F$5)^2/2)/SQRT(2*PI()))*'BS Pricer'!$C$10*EXP(-'BS Pricer'!$C$9*'BS Pricer'!$C$7)/(2*SQRT('BS Pricer'!$C$7))+'BS Pricer'!$C$8*'BS Pricer'!$C$6*EXP(-'BS Pricer'!$C$8*'BS Pricer'!$C$7)*'BS Pricer'!$F$10-'BS Pricer'!$C$9*'BS Pricer'!$C$5*EXP(-'BS Pricer'!$C$9*'BS Pricer'!$C$7)*'BS Pricer'!$F$9)/365 -> -0.027065321 | E8: Time decay per calendar day
B9: Rho (per 1%) | C9: ='BS Pricer'!$C$6*'BS Pricer'!$C$7*EXP(-'BS Pricer'!$C$8*'BS Pricer'!$C$7)*'BS Pricer'!$F$8/100 -> 0.12360163 | D9: =-'BS Pricer'!$C$6*'BS Pricer'!$C$7*EXP(-'BS Pricer'!$C$8*'BS Pricer'!$C$7)*'BS Pricer'!$F$10/100 -> -0.12360163 | E9: Sensitivity to 1pt rate change

Sheet Strategy Payoffs
B2: Payoff at Expiry — Long Straddle Example
B4: Underlying price at expiry -> | C4: 70 | D4: 80 | E4: 90 | F4: 100 | G4: 110 | H4: 120 | I4: 130
B5: Long call payoff | C5: =MAX(C4-'BS Pricer'!$C$6,0) -> 0 | D5: =MAX(D4-'BS Pricer'!$C$6,0) -> 0 | E5: =MAX(E4-'BS Pricer'!$C$6,0) -> 0 | F5: =MAX(F4-'BS Pricer'!$C$6,0) -> 0 | G5: =MAX(G4-'BS Pricer'!$C$6,0) -> 10 | H5: =MAX(H4-'BS Pricer'!$C$6,0) -> 20 | I5: =MAX(I4-'BS Pricer'!$C$6,0) -> 30
B6: Long put payoff | C6: =MAX('BS Pricer'!$C$6-C4,0) -> 30 | D6: =MAX('BS Pricer'!$C$6-D4,0) -> 20 | E6: =MAX('BS Pricer'!$C$6-E4,0) -> 10 | F6: =MAX('BS Pricer'!$C$6-F4,0) -> 0 | G6: =MAX('BS Pricer'!$C$6-G4,0) -> 0 | H6: =MAX('BS Pricer'!$C$6-H4,0) -> 0 | I6: =MAX('BS Pricer'!$C$6-I4,0) -> 0
B7: Net payoff (straddle) | C7: =C5+C6 -> 30 | D7: =D5+D6 -> 20 | E7: =E5+E6 -> 10 | F7: =F5+F6 -> 0 | G7: =G5+G6 -> 10 | H7: =H5+H6 -> 20 | I7: =I5+I6 -> 30
B8: Less: premium paid | C8: ='BS Pricer'!$C$13+'BS Pricer'!$C$14 -> 11.923538 | D8: ='BS Pricer'!$C$13+'BS Pricer'!$C$14 -> 11.923538 | E8: ='BS Pricer'!$C$13+'BS Pricer'!$C$14 -> 11.923538 | F8: ='BS Pricer'!$C$13+'BS Pricer'!$C$14 -> 11.923538 | G8: ='BS Pricer'!$C$13+'BS Pricer'!$C$14 -> 11.923538 | H8: ='BS Pricer'!$C$13+'BS Pricer'!$C$14 -> 11.923538 | I8: ='BS Pricer'!$C$13+'BS Pricer'!$C$14 -> 11.923538
B9: Net P&L | C9: =C7-C8 -> 18.076462 | D9: =D7-D8 -> 8.0764615 | E9: =E7-E8 -> -1.9235385 | F9: =F7-F8 -> -11.923538 | G9: =G7-G8 -> -1.9235385 | H9: =H7-H8 -> 8.0764615 | I9: =I7-I8 -> 18.076462
B11: Note: swap the payoff formulas per leg to model spreads, collars, condors, etc.

Sheet Implied Volatility
B2: Implied Volatility — Newton-Raphson Solver
B4: Inputs
B5: Option type (Call or Put) | C5: Call
B6: Spot price (S) | C6: 100
B7: Strike price (K) | C7: 100
B8: Time to expiry (yrs, T) | C8: 0.25
B9: Risk-free rate (r) | C9: 0.045
B10: Dividend yield (q) | C10: 0
B11: Observed market price (target) | C11: 6.52
B13: Newton-Raphson iterations (converges to machine precision in 2-3 steps for any reasonable option; 9 shown as a safety margin)
C14: Iter 0 | D14: Iter 1 | E14: Iter 2 | F14: Iter 3 | G14: Iter 4 | H14: Iter 5 | I14: Iter 6 | J14: Iter 7 | K14: Iter 8
B15: Sigma (vol estimate) | C15: =SQRT(2*PI()/$C$8)*($C$11/$C$6) -> 0.32686433 | D15: =C15-(C18-$C$11)/C19 -> 0.30054525 | E15: =D15-(D18-$C$11)/D19 -> 0.29995676 | F15: =E15-(E18-$C$11)/E19 -> 0.29994367 | G15: =F15-(F18-$C$11)/F19 -> 0.29994337 | H15: =G15-(G18-$C$11)/G19 -> 0.29994337 | I15: =H15-(H18-$C$11)/H19 -> 0.29994337 | J15: =I15-(I18-$C$11)/I19 -> 0.29994337 | K15: =J15-(J18-$C$11)/J19 -> 0.29994337
B16: d1 | C16: =(LN($C$6/$C$7)+($C$9-$C$10+0.5*C15^2)*$C$8)/(C15*SQRT($C$8)) -> 0.15055198 | D16: =(LN($C$6/$C$7)+($C$9-$C$10+0.5*D15^2)*$C$8)/(D15*SQRT($C$8)) -> 0.15000025 | E16: =(LN($C$6/$C$7)+($C$9-$C$10+0.5*E15^2)*$C$8)/(E15*SQRT($C$8)) -> 0.15 | F16: =(LN($C$6/$C$7)+($C$9-$C$10+0.5*F15^2)*$C$8)/(F15*SQRT($C$8)) -> 0.15 | G16: =(LN($C$6/$C$7)+($C$9-$C$10+0.5*G15^2)*$C$8)/(G15*SQRT($C$8)) -> 0.15 | H16: =(LN($C$6/$C$7)+($C$9-$C$10+0.5*H15^2)*$C$8)/(H15*SQRT($C$8)) -> 0.15 | I16: =(LN($C$6/$C$7)+($C$9-$C$10+0.5*I15^2)*$C$8)/(I15*SQRT($C$8)) -> 0.15 | J16: =(LN($C$6/$C$7)+($C$9-$C$10+0.5*J15^2)*$C$8)/(J15*SQRT($C$8)) -> 0.15 | K16: =(LN($C$6/$C$7)+($C$9-$C$10+0.5*K15^2)*$C$8)/(K15*SQRT($C$8)) -> 0.15
B17: d2 | C17: =C16-C15*SQRT($C$8) -> -0.012880182 | D17: =D16-D15*SQRT($C$8) -> -0.00027237794 | E17: =E16-E15*SQRT($C$8) -> 2.1621944e-05 | F17: =F16-F15*SQRT($C$8) -> 2.8169646e-05 | G17: =G16-G15*SQRT($C$8) -> 2.8315327e-05 | H17: =H16-H15*SQRT($C$8) -> 2.8318569e-05 | I17: =I16-I15*SQRT($C$8) -> 2.8318641e-05 | J17: =J16-J15*SQRT($C$8) -> 2.8318642e-05 | K17: =K16-K15*SQRT($C$8) -> 2.8318642e-05
B18: Price at this sigma | C18: =IF($C$5="Call",$C$6*EXP(-$C$10*$C$8)*NORMSDIST(C16)-$C$7*EXP(-$C$9*$C$8)*NORMSDIST(C17),$C$7*EXP(-$C$9*$C$8)*NORMSDIST(-C17)-$C$6*EXP(-$C$10*$C$8)*NORMSDIST(-C16)) -> 7.0509731 | D18: =IF($C$5="Call",$C$6*EXP(-$C$10*$C$8)*NORMSDIST(D16)-$C$7*EXP(-$C$9*$C$8)*NORMSDIST(D17),$C$7*EXP(-$C$9*$C$8)*NORMSDIST(-D17)-$C$6*EXP(-$C$10*$C$8)*NORMSDIST(-D16)) -> 6.5318715 | E18: =IF($C$5="Call",$C$6*EXP(-$C$10*$C$8)*NORMSDIST(E16)-$C$7*EXP(-$C$9*$C$8)*NORMSDIST(E17),$C$7*EXP(-$C$9*$C$8)*NORMSDIST(-E17)-$C$6*EXP(-$C$10*$C$8)*NORMSDIST(-E16)) -> 6.5202641 | F18: =IF($C$5="Call",$C$6*EXP(-$C$10*$C$8)*NORMSDIST(F16)-$C$7*EXP(-$C$9*$C$8)*NORMSDIST(F17),$C$7*EXP(-$C$9*$C$8)*NORMSDIST(-F17)-$C$6*EXP(-$C$10*$C$8)*NORMSDIST(-F16)) -> 6.5200059 | G18: =IF($C$5="Call",$C$6*EXP(-$C$10*$C$8)*NORMSDIST(G16)-$C$7*EXP(-$C$9*$C$8)*NORMSDIST(G17),$C$7*EXP(-$C$9*$C$8)*NORMSDIST(-G17)-$C$6*EXP(-$C$10*$C$8)*NORMSDIST(-G16)) -> 6.5200001 | H18: =IF($C$5="Call",$C$6*EXP(-$C$10*$C$8)*NORMSDIST(H16)-$C$7*EXP(-$C$9*$C$8)*NORMSDIST(H17),$C$7*EXP(-$C$9*$C$8)*NORMSDIST(-H17)-$C$6*EXP(-$C$10*$C$8)*NORMSDIST(-H16)) -> 6.52 | I18: =IF($C$5="Call",$C$6*EXP(-$C$10*$C$8)*NORMSDIST(I16)-$C$7*EXP(-$C$9*$C$8)*NORMSDIST(I17),$C$7*EXP(-$C$9*$C$8)*NORMSDIST(-I17)-$C$6*EXP(-$C$10*$C$8)*NORMSDIST(-I16)) -> 6.52 | J18: =IF($C$5="Call",$C$6*EXP(-$C$10*$C$8)*NORMSDIST(J16)-$C$7*EXP(-$C$9*$C$8)*NORMSDIST(J17),$C$7*EXP(-$C$9*$C$8)*NORMSDIST(-J17)-$C$6*EXP(-$C$10*$C$8)*NORMSDIST(-J16)) -> 6.52 | K18: =IF($C$5="Call",$C$6*EXP(-$C$10*$C$8)*NORMSDIST(K16)-$C$7*EXP(-$C$9*$C$8)*NORMSDIST(K17),$C$7*EXP(-$C$9*$C$8)*NORMSDIST(-K17)-$C$6*EXP(-$C$10*$C$8)*NORMSDIST(-K16)) -> 6.52
B19: Vega (dPrice/dSigma, raw) | C19: =$C$6*EXP(-$C$10*$C$8)*(EXP(-C16^2/2)/SQRT(2*PI()))*SQRT($C$8) -> 20.174459 | D19: =$C$6*EXP(-$C$10*$C$8)*(EXP(-D16^2/2)/SQRT(2*PI()))*SQRT($C$8) -> 20.172787 | E19: =$C$6*EXP(-$C$10*$C$8)*(EXP(-E16^2/2)/SQRT(2*PI()))*SQRT($C$8) -> 20.172786 | F19: =$C$6*EXP(-$C$10*$C$8)*(EXP(-F16^2/2)/SQRT(2*PI()))*SQRT($C$8) -> 20.172786 | G19: =$C$6*EXP(-$C$10*$C$8)*(EXP(-G16^2/2)/SQRT(2*PI()))*SQRT($C$8) -> 20.172786 | H19: =$C$6*EXP(-$C$10*$C$8)*(EXP(-H16^2/2)/SQRT(2*PI()))*SQRT($C$8) -> 20.172786 | I19: =$C$6*EXP(-$C$10*$C$8)*(EXP(-I16^2/2)/SQRT(2*PI()))*SQRT($C$8) -> 20.172786 | J19: =$C$6*EXP(-$C$10*$C$8)*(EXP(-J16^2/2)/SQRT(2*PI()))*SQRT($C$8) -> 20.172786 | K19: =$C$6*EXP(-$C$10*$C$8)*(EXP(-K16^2/2)/SQRT(2*PI()))*SQRT($C$8) -> 20.172786
B21: Implied volatility (final iteration) | C21: =K15 -> 0.29994337
B22: Convergence check (final price vs. target, should be ~0) | C22: =K18-C11 -> 3.907985e-14

Sheet American Option (Binomial)
B2: American Option Pricing — 10-Step Binomial Tree (Cox-Ross-Rubinstein)
B4: Inputs
B5: Option type (Call or Put) | C5: Put
B6: Spot price (S) | C6: 100
B7: Strike price (K) | C7: 100
B8: Time to expiry (yrs, T) | C8: 1
B9: Risk-free rate (r) | C9: 0.045
B10: Dividend yield (q) | C10: 0
B11: Implied volatility (sigma) | C11: 0.3
B14: Derived tree parameters
B15: Time step (dt = T/N) | C15: =$C$8/10 -> 0.1
B16: Up factor (u = e^(sigma*sqrt(dt))) | C16: =EXP($C$11*SQRT(C15)) -> 1.0995141
B17: Down factor (d = 1/u) | C17: =1/C16 -> 0.90949268
B18: Risk-neutral up-probability (p) | C18: =(EXP(($C$9-$C$10)*C15)-C17)/(C16-C17) -> 0.5000356
B19: Per-step discount factor | C19: =EXP(-$C$9*C15) -> 0.99551011
B21: Underlying Price Tree
B22: t=0 | C22: =$C$6*$C$16^0*$C$17^0 -> 100
B23: t=1 | C23: =$C$6*$C$16^0*$C$17^1 -> 90.949268 | D23: =$C$6*$C$16^1*$C$17^0 -> 109.95141
B24: t=2 | C24: =$C$6*$C$16^0*$C$17^2 -> 82.717693 | D24: =$C$6*$C$16^1*$C$17^1 -> 100 | E24: =$C$6*$C$16^2*$C$17^0 -> 120.89312
B25: t=3 | C25: =$C$6*$C$16^0*$C$17^3 -> 75.231137 | D25: =$C$6*$C$16^1*$C$17^2 -> 90.949268 | E25: =$C$6*$C$16^2*$C$17^1 -> 109.95141 | F25: =$C$6*$C$16^3*$C$17^0 -> 132.92369
B26: t=4 | C26: =$C$6*$C$16^0*$C$17^4 -> 68.422168 | D26: =$C$6*$C$16^1*$C$17^3 -> 82.717693 | E26: =$C$6*$C$16^2*$C$17^2 -> 100 | F26: =$C$6*$C$16^3*$C$17^1 -> 120.89312 | G26: =$C$6*$C$16^4*$C$17^0 -> 146.15146
B27: t=5 | C27: =$C$6*$C$16^0*$C$17^5 -> 62.229461 | D27: =$C$6*$C$16^1*$C$17^4 -> 75.231137 | E27: =$C$6*$C$16^2*$C$17^3 -> 90.949268 | F27: =$C$6*$C$16^3*$C$17^2 -> 109.95141 | G27: =$C$6*$C$16^4*$C$17^1 -> 132.92369 | H27: =$C$6*$C$16^5*$C$17^0 -> 160.69559
B28: t=6 | C28: =$C$6*$C$16^0*$C$17^6 -> 56.597239 | D28: =$C$6*$C$16^1*$C$17^5 -> 68.422168 | E28: =$C$6*$C$16^2*$C$17^4 -> 82.717693 | F28: =$C$6*$C$16^3*$C$17^3 -> 100 | G28: =$C$6*$C$16^4*$C$17^2 -> 120.89312 | H28: =$C$6*$C$16^5*$C$17^1 -> 146.15146 | I28: =$C$6*$C$16^6*$C$17^0 -> 176.68706
B29: t=7 | C29: =$C$6*$C$16^0*$C$17^7 -> 51.474775 | D29: =$C$6*$C$16^1*$C$17^6 -> 62.229461 | E29: =$C$6*$C$16^2*$C$17^5 -> 75.231137 | F29: =$C$6*$C$16^3*$C$17^4 -> 90.949268 | G29: =$C$6*$C$16^4*$C$17^3 -> 109.95141 | H29: =$C$6*$C$16^5*$C$17^2 -> 132.92369 | I29: =$C$6*$C$16^6*$C$17^1 -> 160.69559 | J29: =$C$6*$C$16^7*$C$17^0 -> 194.26991
B30: t=8 | C30: =$C$6*$C$16^0*$C$17^8 -> 46.815931 | D30: =$C$6*$C$16^1*$C$17^7 -> 56.597239 | E30: =$C$6*$C$16^2*$C$17^6 -> 68.422168 | F30: =$C$6*$C$16^3*$C$17^5 -> 82.717693 | G30: =$C$6*$C$16^4*$C$17^4 -> 100 | H30: =$C$6*$C$16^5*$C$17^3 -> 120.89312 | I30: =$C$6*$C$16^6*$C$17^2 -> 146.15146 | J30: =$C$6*$C$16^7*$C$17^1 -> 176.68706 | K30: =$C$6*$C$16^8*$C$17^0 -> 213.6025
B31: t=9 | C31: =$C$6*$C$16^0*$C$17^9 -> 42.578746 | D31: =$C$6*$C$16^1*$C$17^8 -> 51.474775 | E31: =$C$6*$C$16^2*$C$17^7 -> 62.229461 | F31: =$C$6*$C$16^3*$C$17^6 -> 75.231137 | G31: =$C$6*$C$16^4*$C$17^5 -> 90.949268 | H31: =$C$6*$C$16^5*$C$17^4 -> 109.95141 | I31: =$C$6*$C$16^6*$C$17^3 -> 132.92369 | J31: =$C$6*$C$16^7*$C$17^2 -> 160.69559 | K31: =$C$6*$C$16^8*$C$17^1 -> 194.26991 | L31: =$C$6*$C$16^9*$C$17^0 -> 234.85896
B32: t=10 | C32: =$C$6*$C$16^0*$C$17^10 -> 38.725058 | D32: =$C$6*$C$16^1*$C$17^9 -> 46.815931 | E32: =$C$6*$C$16^2*$C$17^8 -> 56.597239 | F32: =$C$6*$C$16^3*$C$17^7 -> 68.422168 | G32: =$C$6*$C$16^4*$C$17^6 -> 82.717693 | H32: =$C$6*$C$16^5*$C$17^5 -> 100 | I32: =$C$6*$C$16^6*$C$17^4 -> 120.89312 | J32: =$C$6*$C$16^7*$C$17^3 -> 146.15146 | K32: =$C$6*$C$16^8*$C$17^2 -> 176.68706 | L32: =$C$6*$C$16^9*$C$17^1 -> 213.6025 | M32: =$C$6*$C$16^10*$C$17^0 -> 258.23073
B34: American Option Value Tree (exercise-or-hold at every node)
B35: t=0 | C35: =MAX(IF($C$5="Call",MAX(C22-$C$7,0),MAX($C$7-C22,0)),$C$19*($C$18*D36+(1-$C$18)*C36)) -> 9.8958083
B36: t=1 | C36: =MAX(IF($C$5="Call",MAX(C23-$C$7,0),MAX($C$7-C23,0)),$C$19*($C$18*D37+(1-$C$18)*C37)) -> 13.864419 | D36: =MAX(IF($C$5="Call",MAX(D23-$C$7,0),MAX($C$7-D23,0)),$C$19*($C$18*E37+(1-$C$18)*D37)) -> 6.0170192
B37: t=2 | C37: =MAX(IF($C$5="Call",MAX(C24-$C$7,0),MAX($C$7-C24,0)),$C$19*($C$18*D38+(1-$C$18)*C38)) -> 18.863768 | D37: =MAX(IF($C$5="Call",MAX(D24-$C$7,0),MAX($C$7-D24,0)),$C$19*($C$18*E38+(1-$C$18)*D38)) -> 8.990834 | E37: =MAX(IF($C$5="Call",MAX(E24-$C$7,0),MAX($C$7-E24,0)),$C$19*($C$18*F38+(1-$C$18)*E38)) -> 3.0978993
B38: t=3 | C38: =MAX(IF($C$5="Call",MAX(C25-$C$7,0),MAX($C$7-C25,0)),$C$19*($C$18*D39+(1-$C$18)*C39)) -> 24.843278 | D38: =MAX(IF($C$5="Call",MAX(D25-$C$7,0),MAX($C$7-D25,0)),$C$19*($C$18*E39+(1-$C$18)*D39)) -> 13.055253 | E38: =MAX(IF($C$5="Call",MAX(E25-$C$7,0),MAX($C$7-E25,0)),$C$19*($C$18*F39+(1-$C$18)*E39)) -> 5.0080878 | F38: =MAX(IF($C$5="Call",MAX(F25-$C$7,0),MAX($C$7-F25,0)),$C$19*($C$18*G39+(1-$C$18)*F39)) -> 1.2159247
B39: t=4 | C39: =MAX(IF($C$5="Call",MAX(C26-$C$7,0),MAX($C$7-C26,0)),$C$19*($C$18*D40+(1-$C$18)*C40)) -> 31.577832 | D39: =MAX(IF($C$5="Call",MAX(D26-$C$7,0),MAX($C$7-D26,0)),$C$19*($C$18*E40+(1-$C$18)*D40)) -> 18.333761 | E39: =MAX(IF($C$5="Call",MAX(E26-$C$7,0),MAX($C$7-E26,0)),$C$19*($C$18*F40+(1-$C$18)*E40)) -> 7.89525 | F39: =MAX(IF($C$5="Call",MAX(F26-$C$7,0),MAX($C$7-F26,0)),$C$19*($C$18*G40+(1-$C$18)*F40)) -> 2.1665077 | G39: =MAX(IF($C$5="Call",MAX(G26-$C$7,0),MAX($C$7-G26,0)),$C$19*($C$18*H40+(1-$C$18)*G40)) -> 0.27644421
B40: t=5 | C40: =MAX(IF($C$5="Call",MAX(C27-$C$7,0),MAX($C$7-C27,0)),$C$19*($C$18*D41+(1-$C$18)*C41)) -> 37.770539 | D40: =MAX(IF($C$5="Call",MAX(D27-$C$7,0),MAX($C$7-D27,0)),$C$19*($C$18*E41+(1-$C$18)*D41)) -> 24.768863 | E40: =MAX(IF($C$5="Call",MAX(E27-$C$7,0),MAX($C$7-E27,0)),$C$19*($C$18*F41+(1-$C$18)*E41)) -> 12.064939 | F40: =MAX(IF($C$5="Call",MAX(F27-$C$7,0),MAX($C$7-F27,0)),$C$19*($C$18*G41+(1-$C$18)*F41)) -> 3.7973672 | G40: =MAX(IF($C$5="Call",MAX(G27-$C$7,0),MAX($C$7-G27,0)),$C$19*($C$18*H41+(1-$C$18)*G41)) -> 0.55542157 | H40: =MAX(IF($C$5="Call",MAX(H27-$C$7,0),MAX($C$7-H27,0)),$C$19*($C$18*I41+(1-$C$18)*H41)) -> 0
B41: t=6 | C41: =MAX(IF($C$5="Call",MAX(C28-$C$7,0),MAX($C$7-C28,0)),$C$19*($C$18*D42+(1-$C$18)*C42)) -> 43.402761 | D41: =MAX(IF($C$5="Call",MAX(D28-$C$7,0),MAX($C$7-D28,0)),$C$19*($C$18*E42+(1-$C$18)*D42)) -> 31.577832 | E41: =MAX(IF($C$5="Call",MAX(E28-$C$7,0),MAX($C$7-E28,0)),$C$19*($C$18*F42+(1-$C$18)*E42)) -> 17.726066 | F41: =MAX(IF($C$5="Call",MAX(F28-$C$7,0),MAX($C$7-F28,0)),$C$19*($C$18*G42+(1-$C$18)*F42)) -> 6.5134394 | G41: =MAX(IF($C$5="Call",MAX(G28-$C$7,0),MAX($C$7-G28,0)),$C$19*($C$18*H42+(1-$C$18)*G42)) -> 1.1159326 | H41: =MAX(IF($C$5="Call",MAX(H28-$C$7,0),MAX($C$7-H28,0)),$C$19*($C$18*I42+(1-$C$18)*H42)) -> 0 | I41: =MAX(IF($C$5="Call",MAX(I28-$C$7,0),MAX($C$7-I28,0)),$C$19*($C$18*J42+(1-$C$18)*I42)) -> 0
B42: t=7 | C42: =MAX(IF($C$5="Call",MAX(C29-$C$7,0),MAX($C$7-C29,0)),$C$19*($C$18*D43+(1-$C$18)*C43)) -> 48.525225 | D42: =MAX(IF($C$5="Call",MAX(D29-$C$7,0),MAX($C$7-D29,0)),$C$19*($C$18*E43+(1-$C$18)*D43)) -> 37.770539 | E42: =MAX(IF($C$5="Call",MAX(E29-$C$7,0),MAX($C$7-E29,0)),$C$19*($C$18*F43+(1-$C$18)*E43)) -> 24.768863 | F42: =MAX(IF($C$5="Call",MAX(F29-$C$7,0),MAX($C$7-F29,0)),$C$19*($C$18*G43+(1-$C$18)*F43)) -> 10.844153 | G42: =MAX(IF($C$5="Call",MAX(G29-$C$7,0),MAX($C$7-G29,0)),$C$19*($C$18*H43+(1-$C$18)*G43)) -> 2.2420909 | H42: =MAX(IF($C$5="Call",MAX(H29-$C$7,0),MAX($C$7-H29,0)),$C$19*($C$18*I43+(1-$C$18)*H43)) -> 0 | I42: =MAX(IF($C$5="Call",MAX(I29-$C$7,0),MAX($C$7-I29,0)),$C$19*($C$18*J43+(1-$C$18)*I43)) -> 0 | J42: =MAX(IF($C$5="Call",MAX(J29-$C$7,0),MAX($C$7-J29,0)),$C$19*($C$18*K43+(1-$C$18)*J43)) -> 0
B43: t=8 | C43: =MAX(IF($C$5="Call",MAX(C30-$C$7,0),MAX($C$7-C30,0)),$C$19*($C$18*D44+(1-$C$18)*C44)) -> 53.184069 | D43: =MAX(IF($C$5="Call",MAX(D30-$C$7,0),MAX($C$7-D30,0)),$C$19*($C$18*E44+(1-$C$18)*D44)) -> 43.402761 | E43: =MAX(IF($C$5="Call",MAX(E30-$C$7,0),MAX($C$7-E30,0)),$C$19*($C$18*F44+(1-$C$18)*E44)) -> 31.577832 | F43: =MAX(IF($C$5="Call",MAX(F30-$C$7,0),MAX($C$7-F30,0)),$C$19*($C$18*G44+(1-$C$18)*F44)) -> 17.282307 | G43: =MAX(IF($C$5="Call",MAX(G30-$C$7,0),MAX($C$7-G30,0)),$C$19*($C$18*H44+(1-$C$18)*G44)) -> 4.5047269 | H43: =MAX(IF($C$5="Call",MAX(H30-$C$7,0),MAX($C$7-H30,0)),$C$19*($C$18*I44+(1-$C$18)*H44)) -> 0 | I43: =MAX(IF($C$5="Call",MAX(I30-$C$7,0),MAX($C$7-I30,0)),$C$19*($C$18*J44+(1-$C$18)*I44)) -> 0 | J43: =MAX(IF($C$5="Call",MAX(J30-$C$7,0),MAX($C$7-J30,0)),$C$19*($C$18*K44+(1-$C$18)*J44)) -> 0 | K43: =MAX(IF($C$5="Call",MAX(K30-$C$7,0),MAX($C$7-K30,0)),$C$19*($C$18*L44+(1-$C$18)*K44)) -> 0
B44: t=9 | C44: =MAX(IF($C$5="Call",MAX(C31-$C$7,0),MAX($C$7-C31,0)),$C$19*($C$18*D45+(1-$C$18)*C45)) -> 57.421254 | D44: =MAX(IF($C$5="Call",MAX(D31-$C$7,0),MAX($C$7-D31,0)),$C$19*($C$18*E45+(1-$C$18)*D45)) -> 48.525225 | E44: =MAX(IF($C$5="Call",MAX(E31-$C$7,0),MAX($C$7-E31,0)),$C$19*($C$18*F45+(1-$C$18)*E45)) -> 37.770539 | F44: =MAX(IF($C$5="Call",MAX(F31-$C$7,0),MAX($C$7-F31,0)),$C$19*($C$18*G45+(1-$C$18)*F45)) -> 24.768863 | G44: =MAX(IF($C$5="Call",MAX(G31-$C$7,0),MAX($C$7-G31,0)),$C$19*($C$18*H45+(1-$C$18)*G45)) -> 9.050732 | H44: =MAX(IF($C$5="Call",MAX(H31-$C$7,0),MAX($C$7-H31,0)),$C$19*($C$18*I45+(1-$C$18)*H45)) -> 0 | I44: =MAX(IF($C$5="Call",MAX(I31-$C$7,0),MAX($C$7-I31,0)),$C$19*($C$18*J45+(1-$C$18)*I45)) -> 0 | J44: =MAX(IF($C$5="Call",MAX(J31-$C$7,0),MAX($C$7-J31,0)),$C$19*($C$18*K45+(1-$C$18)*J45)) -> 0 | ... L44: =MAX(IF($C$5="Call",MAX(L31-$C$7,0),MAX($C$7-L31,0)),$C$19*($C$18*M45+(1-$C$18)*L45)) -> 0
B45: t=10 | C45: =IF($C$5="Call",MAX(C32-$C$7,0),MAX($C$7-C32,0)) -> 61.274942 | D45: =IF($C$5="Call",MAX(D32-$C$7,0),MAX($C$7-D32,0)) -> 53.184069 | E45: =IF($C$5="Call",MAX(E32-$C$7,0),MAX($C$7-E32,0)) -> 43.402761 | F45: =IF($C$5="Call",MAX(F32-$C$7,0),MAX($C$7-F32,0)) -> 31.577832 | G45: =IF($C$5="Call",MAX(G32-$C$7,0),MAX($C$7-G32,0)) -> 17.282307 | H45: =IF($C$5="Call",MAX(H32-$C$7,0),MAX($C$7-H32,0)) -> 0 | I45: =IF($C$5="Call",MAX(I32-$C$7,0),MAX($C$7-I32,0)) -> 0 | J45: =IF($C$5="Call",MAX(J32-$C$7,0),MAX($C$7-J32,0)) -> 0 | ... M45: =IF($C$5="Call",MAX(M32-$C$7,0),MAX($C$7-M32,0)) -> 0
B47: European Option Value Tree (hold-only — comparison / BS cross-check)
...

Sheet RefreshLog
B2: Refresh Log
B4: Date | C4: Trigger | D4: What changed | E4: Reviewer notes | F4: Next check
